<?xml version="1.0" ?>
<!-- =================================================================================== -->
<!-- |    This document was autogenerated by xacro from src/taser_ros/urdf/robot.urdf.xacro | -->
<!-- |    EDITING THIS FILE BY HAND IS NOT RECOMMENDED                                 | -->
<!-- =================================================================================== -->
<robot name="taser">
  <material name="blue">
    <color rgba="0 0.1 0.5 1"/>
  </material>
  <material name="light-blue">
    <color rgba="0 0.3 0.7 1"/>
  </material>
  <material name="white">
    <color rgba="0.5 0.5 1 1"/>
  </material>
  <material name="pink">
    <color rgba="0.3 0 0.2 1"/>
  </material>
  <ros2_control name="taser" type="system">
    <hardware>
      <plugin>mock_components/GenericSystem</plugin>
      <param name="calculate_dynamics">true</param>
    </hardware>
    <joint name="base_left_arm_1_joint">
      <command_interface name="velocity"/>
      <state_interface name="position"/>
      <state_interface name="velocity"/>
    </joint>
    <joint name="left_arm_1_left_arm_2_joint">
      <command_interface name="velocity"/>
      <state_interface name="position"/>
      <state_interface name="velocity"/>
    </joint>
    <joint name="left_arm_2_left_arm_3_joint">
      <command_interface name="velocity"/>
      <state_interface name="position"/>
      <state_interface name="velocity"/>
    </joint>
    <joint name="base_right_arm_1_joint">
      <command_interface name="velocity"/>
      <state_interface name="position"/>
      <state_interface name="velocity"/>
    </joint>
    <joint name="right_arm_1_right_arm_2_joint">
      <command_interface name="velocity"/>
      <state_interface name="position"/>
      <state_interface name="velocity"/>
    </joint>
    <joint name="right_arm_2_right_arm_3_joint">
      <command_interface name="velocity"/>
      <state_interface name="position"/>
      <state_interface name="velocity"/>
    </joint>
    <joint name="base_wheel_1_joint">
      <command_interface name="velocity"/>
      <state_interface name="position"/>
      <state_interface name="velocity"/>
    </joint>
    <joint name="base_wheel_2_joint">
      <command_interface name="velocity"/>
      <state_interface name="position"/>
      <state_interface name="velocity"/>
    </joint>
    <!-- <joint name="wheel_3_base_wheel_3_steering_joint">
        <command_interface name="velocity" />
        <state_interface name="position" />
        <state_interface name="velocity" />
      </joint>

      <joint name="wheel_3_steering_wheel_3_joint">
        <command_interface name="velocity" />
        <state_interface name="position" />
        <state_interface name="velocity" />
      </joint> -->
  </ros2_control>
  <!-- map -> odom - Localization corrections (ex. SLAM) -->
  <link name="map"/>
  <!-- odom -> base - Robot motion relative to starting position -->
  <link name="odom"/>
  <joint name="map_odom_joint" type="fixed">
    <origin rpy="0.0 0.0 0" xyz="0.0 0.0 0.0"/>
    <parent link="map"/>
    <child link="odom"/>
  </joint>
  <!-- Base wrapper link to get a frame with z=0 -->
  <link name="base_wrapper"/>
  <link name="base">
    <visual>
      <origin rpy="0.0 0.0 0.0" xyz="0.0 0.0 0.0"/>
      <geometry>
        <box size="0.8 2 3.5"/>
      </geometry>
      <material name="blue"/>
    </visual>
    <collision>
      <origin rpy="0.0 0.0 0.0" xyz="0.0 0.0 0.0"/>
      <geometry>
        <box size="0.8 2 3.5"/>
      </geometry>
    </collision>
  </link>
  <joint name="base_wrapper_base_joint" type="fixed">
    <origin rpy="0.0 0.0 0" xyz="0.0 0.0 2.25"/>
    <parent link="base_wrapper"/>
    <child link="base"/>
  </joint>
  <joint name="odom_base_wrapper_joint" type="fixed">
    <origin rpy="0.0 0.0 0" xyz="0.0 0.0 0.0"/>
    <parent link="odom"/>
    <child link="base_wrapper"/>
  </joint>
  <link name="left_arm_1">
    <visual>
      <origin rpy="0.0 0.0 0.0" xyz="0.0 0.0 -0.5"/>
      <geometry>
        <box size="0.5 0.25 1"/>
      </geometry>
      <material name="light-blue"/>
    </visual>
    <collision>
      <origin rpy="0.0 0.0 0.0" xyz="0.0 0.0 -0.5"/>
      <geometry>
        <box size="0.5 0.25 1"/>
      </geometry>
    </collision>
  </link>
  <joint name="base_left_arm_1_joint" type="continuous">
    <parent link="base"/>
    <child link="left_arm_1"/>
    <origin rpy="0.0 0.0 0.0" xyz="0.0 1.125 1.5"/>
    <axis xyz="0 1 0"/>
  </joint>
  <link name="left_arm_2">
    <visual>
      <origin rpy="0.0 0.0 0.0" xyz="0.0 0.0 -0.25"/>
      <geometry>
        <box size="0.25 0.25 0.5"/>
      </geometry>
      <material name="white"/>
    </visual>
    <collision>
      <origin rpy="0.0 0.0 0.0" xyz="0.0 0.0 -0.25"/>
      <geometry>
        <box size="0.25 0.25 0.5"/>
      </geometry>
    </collision>
  </link>
  <joint name="left_arm_1_left_arm_2_joint" type="continuous">
    <parent link="left_arm_1"/>
    <child link="left_arm_2"/>
    <origin rpy="0.0 0.0 0.0" xyz="0.0 0 -1"/>
    <axis xyz="0 0 1"/>
  </joint>
  <link name="left_arm_3">
    <visual>
      <origin rpy="0.0 0.0 0.0" xyz="0.0 0.0 -0.5"/>
      <geometry>
        <box size="0.25 0.25 1"/>
      </geometry>
      <material name="light-blue"/>
    </visual>
    <collision>
      <origin rpy="0.0 0.0 0.0" xyz="0.0 0.0 -0.5"/>
      <geometry>
        <box size="0.25 0.25 1"/>
      </geometry>
    </collision>
  </link>
  <joint name="left_arm_2_left_arm_3_joint" type="continuous">
    <parent link="left_arm_2"/>
    <child link="left_arm_3"/>
    <origin rpy="0.0 0.0 0.0" xyz="0.0 0 -0.5"/>
    <axis xyz="0 1 0"/>
  </joint>
  <link name="left_arm_eef">
        </link>
  <joint name="left_arm_3_left_arm_eef_joint" type="fixed">
    <parent link="left_arm_3"/>
    <child link="left_arm_eef"/>
    <origin rpy="0.0 0.0 0.0" xyz="0.0 0 -1"/>
  </joint>
  <link name="right_arm_1">
    <visual>
      <origin rpy="0.0 0.0 0.0" xyz="0.0 0.0 -0.5"/>
      <geometry>
        <box size="0.5 0.25 1"/>
      </geometry>
      <material name="light-blue"/>
    </visual>
    <collision>
      <origin rpy="0.0 0.0 0.0" xyz="0.0 0.0 -0.5"/>
      <geometry>
        <box size="0.5 0.25 1"/>
      </geometry>
    </collision>
  </link>
  <joint name="base_right_arm_1_joint" type="continuous">
    <parent link="base"/>
    <child link="right_arm_1"/>
    <origin rpy="0.0 0.0 0.0" xyz="0.0 -1.125 1.5"/>
    <axis xyz="0 1 0"/>
  </joint>
  <link name="right_arm_2">
    <visual>
      <origin rpy="0.0 0.0 0.0" xyz="0.0 0.0 -0.25"/>
      <geometry>
        <box size="0.25 0.25 0.5"/>
      </geometry>
      <material name="white"/>
    </visual>
    <collision>
      <origin rpy="0.0 0.0 0.0" xyz="0.0 0.0 -0.25"/>
      <geometry>
        <box size="0.25 0.25 0.5"/>
      </geometry>
    </collision>
  </link>
  <joint name="right_arm_1_right_arm_2_joint" type="continuous">
    <parent link="right_arm_1"/>
    <child link="right_arm_2"/>
    <origin rpy="0.0 0.0 0.0" xyz="0.0 0 -1"/>
    <axis xyz="0 0 1"/>
  </joint>
  <link name="right_arm_3">
    <visual>
      <origin rpy="0.0 0.0 0.0" xyz="0.0 0.0 -0.5"/>
      <geometry>
        <box size="0.25 0.25 1"/>
      </geometry>
      <material name="light-blue"/>
    </visual>
    <collision>
      <origin rpy="0.0 0.0 0.0" xyz="0.0 0.0 -0.5"/>
      <geometry>
        <box size="0.25 0.25 1"/>
      </geometry>
    </collision>
  </link>
  <joint name="right_arm_2_right_arm_3_joint" type="continuous">
    <parent link="right_arm_2"/>
    <child link="right_arm_3"/>
    <origin rpy="0.0 0.0 0.0" xyz="0.0 0 -0.5"/>
    <axis xyz="0 1 0"/>
  </joint>
  <link name="right_arm_eef">
        </link>
  <joint name="right_arm_3_right_arm_eef_joint" type="fixed">
    <parent link="right_arm_3"/>
    <child link="right_arm_eef"/>
    <origin rpy="0.0 0.0 0.0" xyz="0.0 0 -1"/>
  </joint>
  <link name="wheel_1">
    <visual>
      <origin rpy="1.575 0.0 0.0" xyz="0.0 0.0 0.0"/>
      <geometry>
        <cylinder length="0.25" radius="0.5"/>
      </geometry>
      <material name="pink"/>
    </visual>
    <collision>
      <origin rpy="1.575 0.0 0.0" xyz="0.0 0.0 0.0"/>
      <geometry>
        <cylinder length="0.25" radius="0.5"/>
      </geometry>
    </collision>
  </link>
  <joint name="base_wheel_1_joint" type="continuous">
    <parent link="base"/>
    <child link="wheel_1"/>
    <origin rpy="0.0 0.0 0.0" xyz="0.0 1.125 -1.75"/>
    <axis xyz="0 1 0"/>
  </joint>
  <link name="wheel_2">
    <visual>
      <origin rpy="1.575 0.0 0.0" xyz="0.0 0.0 0.0"/>
      <geometry>
        <cylinder length="0.25" radius="0.5"/>
      </geometry>
      <material name="pink"/>
    </visual>
    <collision>
      <origin rpy="1.575 0.0 0.0" xyz="0.0 0.0 0.0"/>
      <geometry>
        <cylinder length="0.25" radius="0.5"/>
      </geometry>
    </collision>
  </link>
  <joint name="base_wheel_2_joint" type="continuous">
    <parent link="base"/>
    <child link="wheel_2"/>
    <origin rpy="0.0 0.0 0.0" xyz="0.0 -1.125 -1.75"/>
    <axis xyz="0 1 0"/>
  </joint>
</robot>
